## try..catch와 에러 핸들링

Java뿐만 아니라 자바스크립트에서도 `실수, 예상치 못한 사용자 입력, 잘못된 서버 응답 등`의 수천만 가지 이유 때문에 스크립트가 사망할 수 있는 것을 방지하기 위해 try..catch문을 지원하고 있습니다.

그러나 try..catch 문법을 사용하면 스크립트가 죽는 걸 방지하고, 에러를 잡아서(catch) 더 합당한 무언가를 할 수 있게 됩니다.

## try..catch 문법

```javascript
try {
    // 코드...
} catch (err) {
    // 에러 핸들링
}
```

try..catch 동작 알고리즘은 자바와 동일합니다.

1. 먼저 try {...} 안의 코드가 실행됩니다.
2. 에러가 없다면, try 안의 마지막 줄까지 실행되고, catch 블록은 건너뜁니다.
3. 에러가 있다면, try안 코드의 실행이 중단되고, catch(err) 블록으로 제어 흐름이 넘어갑니다. 변수 err(아무 이름이나 사용 가능) 무슨 일어났는지에 대한 설명이 담긴 여러 객체를 포함합니다.

>> try..catch 문은 오직 런타임 에러에만 동작합니다. 실행 가능한 코드는 유요한 자바스크립트 코드를 의미합니다. 중괄호 짝이 안 맞는 것처럼 코드가 문법적으로 잘못된 경우엔 try..catch가 동작하지 않습니다.

```javascript
try {
    {{{{{{{{{
} catch (e) {
    alert('유효하지 않는 코드이기 때문에, 자바스크립트 엔진은 이 코드를 이해할 수 없습니다.');
}
```

자바스크립트 엔진은 코드를 일고 난 후 코드를 실행합니다. 코드를 읽는 중에 발생하는 에러는 `parse-time` 에러라고 부르는데, 엔진은 이 코드를 이해할 수 없기 때문에 parse-time 에러는 코드 안에서 복구가 불가능합니다.

try..catch는 유효한 코드에서 발생하는 에러만 처리할 수 있습니다. 이런 에러를 `런타임 에러(runtime error)` 혹은 `예외(exception)`라고 부릅니다.


try..catch는 동기적으로 동작합니다.

setTimeout 처럼 `스케줄 된` 코드에서 발생한 예외는 try..catch로 잡아낼 수 없습니다.

```javascript
try {
    setTimeout(function() {
        noSuchVariable; // 스크립트는 여기서 사망
    }, 1000);
} catch (e) {
    alert('동작 멈춤');
}
```

setTimeout에 넘겨진 익명 함수는 엔진인 try..catch를 떠난 다음에서야 실행되기 때문입니다. 스케줄 된 함수 내부의 예외를 잡으려면, try..catch를 반드시 함수 내부에 구현해야 합니다.

```javascript
setTimeout(function() {
    try {
        noSuchVariable; // 이제 try..catch에서 에러를 핸들링 할 수 있습니다.
    } catch {
        alert('에러를 잡았습니다!!');
    }
}, 1000);
```

## 에러 객체 
에러가 발생하면 자바스크립트는 에러 상세내용이 담긴 객체를 생성합니다. 그 후 catch 블록에 이 객체를 인수로 전달합니다.

```javascript
try {
    / ...
} catch (err) { // <-- 에러 객체, err 대신 다른 이름으로 사용 가능합니다.
    // ...
}
```
내장 에러 전체와 에러 객체는 두 가지 주요 프로퍼티를 가집니다.

- name: 에러 이름, 정의되지 않는 변수 때문에 발생한 에러라면 `ReferenceError`가 이름이 됩니다.


- message: 에러 상세 내용을 담고 있는 문자 메시지

표준은 아니지만, name과 message 이외에 대부분의 호스트 환경에서 지원하는 프로퍼티도 있습ㄴ다. stack은 가장 널리 사용되는 비표준 프로퍼티 중 하나입니다.

- stack: 현재 호출 스택, 에러를 유발한 중첩 호출들의 순서 정보를 가진 문자열로 디버깅 목적으로 사용됩니다.

```javascript
try {
  lalala; // 에러, 변수가 정의되지 않음!
} catch(err) {
  alert(err.name); // ReferenceError
  alert(err.message); // lalala is not defined
  alert(err.stack); // ReferenceError: lalala is not defined at ... (호출 스택)

  // 에러 전체를 보여줄 수도 있습니다.
  // 이때, 에러 객체는 "name: message" 형태의 문자열로 변환됩니다.
  alert(err); // ReferenceError: lalala is not defined
}
```

## 선택적 catch 바인딩

에러에 대한 자세한 정보가 필요하지 않으면, catch에서 이를 생략할 수 있습니다.

```javascript
try {
    // ...
} catch{ // <-- (err) 없이 쓸 수 있음
    //...
}
```


## throw 연산자

throw 연산자는 에러를 생성합니다.
문법은 아래와 같습니다.

```javascript
throw <error object>
```

이론적으로 숫자, 문자열 같은 원시형 자료를 포함한 어떤 것이든 에러 객체를 사용할 수 있습니다. 하지만 내장 에러와 호환을 위해 되도록 에러 객체에 name과 message 프로퍼티를 넣어주는 것을 권장합니다.

자바스크립트는 Error, SyntaxError, ReferenceError, TypeError등의 표준 에러 객체 관련 생성자를 지원합니다. 이 생성자들을 이용해 에러 객체를 만들 수도 있습니다.

```javascript
let error = new Error(message);
// or
let error = new SyntaxError(message);
let error = new ReferenceError(message);
// ...
```

일반 객체가 아닌 내장 생성자를 사용해 만든 내장 에러 객체의 name 프로퍼티는 생성자 이름과 동일한 값을 같습니다. 프로퍼티 message의 값은 인수에서 가져옵니다.

ex)

```javascript
let error = new Error("이상한 일이 발생했습니다. o_0");

alert(error.name); // Error
alert(error.message); // 이상한 일이 발생했습니다. o_0
```

잘못된 데이터를 받았을 때, JSON.parse가 어떤 종류의 에러를 만들어내는지 아래 코드를 통해 살펴보겠습니다.

```javascript
try {
    JSON.parse("{잘못된 형식의 json o_0}");
} catch (e) {
    alert(e.name); // SyntaxError
    alert(e.message); // Unexpected token b in JSON at position 2
}
```

Syntax 에러가 발생합니다. 사용자를 나타내는 객체에 name 프로퍼티는 반드시 있어야 하므로, 이제 name이 없으면 에러가 발생한것으로 간주하고 예외 처리를 하는 예제를 살펴보겠습니다. throw 연산자를 사용해 에러를 던졌습니다.

```javascript
let json = '{ "age": 30 }'; // 불완전한 데이터

try {

  let user = JSON.parse(json); // <-- 에러 없음

  if (!user.name) {
    throw new SyntaxError("불완전한 데이터: 이름 없음"); // (*)
  }

  alert( user.name );

} catch(e) {
  alert( "JSON Error: " + e.message ); // JSON Error: 불완전한 데이터: 이름 없음
}
```
(*)로 표시한 줄에서 throw 연산자는 message를 이용해 SyntaxError 객체를 생성합니다. 에러 생성 방식은 자바스크립트가 자체적으로 에러를 생성하는 방식과 동일합니다. 에러가 발생하므로서 try의 실행은 즉시 중단되고 제어 흐름이 catch로 넘어간 것을 얼럿 창을 통해 확인할 수 있습니다.

## 에러 다시 던지기 

```javascript
let json = '{ "age": 30 }'; // 불완전한 데이터

try {
  user = JSON.parse(json); // <-- user 앞에 let이 생략됨

  // ...
} catch(err) {
  alert("JSON Error: " + err); // JSON Error: ReferenceError: user is not defined
  // (실제론 JSON Error가 아닙니다.)
}
```

에러는 어떠한 상황에서도 발생할 수 있습니다. 위에선 불완전한 데이터를 다루려는 목적으로 try..catch를 썼습니다. 그런데 catch는 원래 try 블록에서 발생한 모든 에러를 잡으려는 목적으로 만들어졌습니다. 그런데 위 예시에서 catch는 예상치 못한 에러를 잡아내 주긴 했지만, 에러 종류와 관계없이 `JSON Error` 메시지를 보여줍니다. 이렇게 에러 종류와 관계없이 동일한 방식으로 에러를 처리하는 것은 디버깅을 어렵게 만들기 때문에 좋지 않습니다.

에러를 다시 던져서 catch 블록에선 SyntaxError만 처리되도록 하면 아래와 같습니다.

```javascript
try {
    let json = '{ "age": 30 }';

    if (!user.name) {
        throw new SyntaxError("불완전한 데이터: 이름 없음");
    }

    blabla(); // 예상치 못한 에러
    alert(user.name);

} catch (e) {

    if (e instanceof SyntaxError) {
        alert("JSON Error: " + e.message);
    } else {
        throw e; // 에러 다시 던지기 (*)
    }
}
```

catch 블록 안의 (*) 표시한 줄에 다시 던져진 에러는 try..catch 밖으로 던져집니다. 이때 바깥에 try..catch가 있다면 여기서 에러를 잡습니다. 아니라면 스크립트는 죽을 겁니다.

아재 try..catch를 하나 더 만들어, 다시 던져진 예상치 못한 에러를 처리해 보겠습니다.

```javascript
function readData() {

    let json = "{ "age": 30}";

    try {
        //.. do something
        blabla(); // 에러!
    } catch (e) {
        if (!(e instanceof SyntaxError)) {
            throw e; // 알 수 없는 에러 다시 던지기
        }
    }
}

try {
    readData();
} catch (e) {
    alert("External catch got: " + e); // 에러를 잡읍
}
```

readData는 SyntaxError만 처리할 수 있지만, 함수 바깥의 try..catch에서는 예상치 못한 에러도 처리할 수 있게 되었습니다.

아래에 예외를 다양하게 처리하는 예제입니다. 해당하는 예외 인스턴스에 속하지 않으면
다시 던지도록 합니다.

```javascript
try {
  ...
  readUser()  // 잠재적 에러 발생처
  ...
} catch (err) {
  if (err instanceof ValidationError) {
    // validation 에러 처리
  } else if (err instanceof SyntaxError) {
    // 문법 에러 처리
  } else {
    throw err; // 알 수 없는 에러는 다시 던지기 함
  }
}
```

## 에러확장하기

사용자 데이터가 저장된 JSON을 읽는 함수 readUser(json)가 있다고 해봅시다.
유효한 json은 다음과 같은 형태이어야 합니다.

```javascript
let json = '{ "name": "John", "age": 30 }';
```

readUser 내부에선 JSON.parse를 이용하게 됩니다. 따라서 잘못된 형식의 json이 들어오면 SyntaxError가 발생하겠죠. 그런데 인수로 받은 데이터가 JSON 형식이긴 하지만, 유효한 사용자일 것이라는 보장은 없습니다. 사용자 데이터라면 필수적으로 있어야 할 name이나 age가 누락되었을 수 있습니다.

따라서 readUser(json)은 JSON 형식의 데이터를 읽을 수 있을 뿐만 아니라, 데이터를 '검증'할 수 있어야 합니다. 필수 프로퍼티가 없거나, 위 형식에 맞지 않으면 에러를 발생시킬 수 있어야 합니다.

그러나 이때 발생하는 에러는 SyntaxError가 아닙니다. JSON 형식은 맞지만, 자체 기준에 맞지 않기 때문에 발생한 에러이므로 전혀 다른 종류의 에러입니다. 이 에러 코드를 ValidationError라고 부르겠습니다. 

ValidationError 클래스엔 문제가 되는 필드 정보가 저장되어야 합니다. 내장 클래스 Error를 상속받아 ValidationError 클래스를 만들어보겠습니다.

```javascript
// 자바스크립트 자체 내장 에러 클래스 Error의 '슈도 코드'
class Error {
  constructor(message) {
    this.message = message;
    this.name = "Error"; // (name은 내장 에러 클래스마다 다릅니다.)
    this.stack = <call stack>;  // stack은 표준은 아니지만, 대다수 환경이 지원합니다.
  }
}
```

이제 ValidationError에서 Error를 상속받아보겠습니다.

```javascript
class ValidationError extends Error {
  constructor(message) {
    super(message); // (1)
    this.name = "ValidationError"; // (2)
  }
}

function test() {
  throw new ValidationError("에러 발생!");
}

try {
  test();
} catch(err) {
  alert(err.message); // 에러 발생!
  alert(err.name); // ValidationError
  alert(err.stack); // 각 행 번호가 있는 중첩된 호출들의 목록
}
```

(1)에서 부모 생성자를 호출하고 있다는 것에 주목해 주시기 바랍니다. 자바스크립트에서는 자식 생성자 안에서 super를 반드시 호출해야 합니다. message 프로퍼티는 부모 생성자에서 설정됩니다.
부모 생성자에선 message뿐만 아니라 name 프로퍼티도 설정("Error")하기 때문에, (2)에서 원하는 값으로 재설정해주었습니다.


#### 참조: https://ko.javascript.info/try-catch
